# Higgs Audio DynamicCache Bug Analysis - Issue #138

## Problem Summary

Users get `AttributeError: 'NoneType' object has no attribute 'zero_'` when using Higgs Audio 2 Engine with TTS Text node.

Error location:
```
File "serve_engine.py", line 667, in _prepare_kv_caches
    kv_cache.reset()
File "transformers/cache_utils.py", line 1247, in reset
    self.layers[layer_idx].reset()
File "transformers/cache_utils.py", line 55, in reset
    self.keys.zero_()  # <-- AttributeError: 'NoneType' has no attribute 'zero_'
```

## Root Cause Analysis

The issue is in `engines/higgs_audio/boson_multimodal/serve/serve_engine.py` lines 662-671:

```python
# Reset all caches (StaticCache has reset(), DynamicCache needs manual clearing)
from transformers.cache_utils import DynamicCache
for kv_cache in self.kv_caches.values():
    if hasattr(kv_cache, 'reset'):
        # StaticCache has built-in reset method
        kv_cache.reset()  # LINE 667 - ERROR HAPPENS HERE
    elif isinstance(kv_cache, DynamicCache):
        # DynamicCache needs manual clearing - use new API
        kv_cache.crop(0)  # Clear all cached states
```

### Why the Error Occurs

1. **Manual DynamicCache Creation** (lines 636-641):
   ```python
   cache = object.__new__(DynamicCache)
   object.__setattr__(cache, '_key_cache', [])
   object.__setattr__(cache, '_value_cache', [])
   ```
   This creates a DynamicCache without proper initialization of internal layer structure.

2. **hasattr() Check Flaw** (line 665):
   ```python
   if hasattr(kv_cache, 'reset'):
   ```
   Both StaticCache AND DynamicCache have a `reset()` method. So when a manually-created DynamicCache is used, it matches the first condition instead of the `isinstance(kv_cache, DynamicCache)` check.

3. **Method Resolution Order Problem**:
   - If the manually-created DynamicCache has a `reset()` method, it will be called
   - This `reset()` method tries to iterate over `self.layers` and call `zero_()` on keys/values
   - But since the cache wasn't properly initialized, `self.keys` is `None`

### When This Happens

This issue manifests when:
- User has CUDA Graphs DISABLED (Memory Safe mode) → uses DynamicCache manually created (line 632 try/except)
- The try/except at line 631-643 catches an AttributeError and manually creates the cache
- Later when `_prepare_kv_caches()` is called again, the manually-created DynamicCache object exists
- The `hasattr(kv_cache, 'reset')` check passes because DynamicCache has a reset method
- But calling `.reset()` on a manually-created, improperly-initialized DynamicCache fails

## Why It's Inconsistent

This bug is **hard to reproduce reliably** because:

1. **Exception Handling**: The try/except at line 631 only triggers if DynamicCache() constructor raises AttributeError
   - Different transformers versions handle this differently
   - Some versions raise AttributeError, others don't
   - User's environment (transformers 2.7.0+cu128) apparently triggers this

2. **Cache State**: Once manually created, the cache object persists and its state gets used later
   - If the cache was never in memory safe mode during initialization, the issue doesn't manifest
   - Device mismatches or state changes can trigger the problem

## Solution Options

### Option 1: Use `isinstance()` Check Instead of `hasattr()` (SAFEST)
```python
from transformers.cache_utils import DynamicCache, StaticCache

for kv_cache in self.kv_caches.values():
    if isinstance(kv_cache, StaticCache):
        kv_cache.reset()
    elif isinstance(kv_cache, DynamicCache):
        kv_cache.crop(0)
    else:
        # Unknown cache type - skip reset
        pass
```

**Pros:**
- Type-safe, explicit about what we're resetting
- Handles both properly-initialized and manually-created DynamicCache correctly
- No ambiguity about method resolution

**Cons:**
- Need to import both cache types
- Slightly more verbose

### Option 2: Wrap Reset in Try/Except
```python
for kv_cache in self.kv_caches.values():
    if hasattr(kv_cache, 'reset'):
        try:
            kv_cache.reset()
        except (AttributeError, TypeError) as e:
            # Fallback for improperly initialized caches
            if hasattr(kv_cache, 'crop'):
                kv_cache.crop(0)
            else:
                print(f"⚠️ Could not reset cache: {e}")
    elif isinstance(kv_cache, DynamicCache):
        kv_cache.crop(0)
```

**Pros:**
- Graceful degradation
- Works with any cache type
- Catches other potential reset errors

**Cons:**
- Silent failure on error
- Doesn't address root cause of bad state

### Option 3: Improve Manual DynamicCache Creation
Properly initialize the manually-created DynamicCache to match transformers' expectations.

**Pros:**
- Fixes the root cause
- Cache will be properly functional

**Cons:**
- Need to reverse-engineer transformers' internal structure
- May break with transformers version updates
- More complex code

## Recommendation

**Use Option 1** - it's the cleanest, most maintainable solution that directly addresses the design issue. The code is already trying to handle StaticCache vs DynamicCache differently (line 668-671), so using explicit type checks is the right approach.

## Secondary Issue

Even after fixing the reset logic, there's a design issue: why are we even creating DynamicCache manually with `object.__new__()`?

The proper solution would be:
1. Check transformers version
2. Use the appropriate cache creation method for that version
3. Don't manually construct cache objects

Or simply rely on the `past_key_values_buckets` parameter that transformers handles internally.

## Testing

To verify this issue:
1. User with Higgs Audio + Memory Safe Mode (CUDA Graphs OFF)
2. Where transformers raises AttributeError on DynamicCache()
3. Attempting generation triggers `_prepare_kv_caches()`
4. Error occurs on `.reset()` call

